<mujoco model="franka_ag95">
  <compiler angle="radian" meshdir="assets" autolimits="true"/>
  <option integrator="implicitfast" impratio="10"/>
  <default>
    <default class="panda_arm_only">
      <material specular="0.5" shininess="0.25"/>
      <joint armature="0.1" damping="1" range="-2.8973 2.8973"/>
      <general dyntype="none" biastype="affine" ctrlrange="-2.8973 2.8973" forcerange="-87 87"/>
      <default class="finger">
        <joint axis="0 1 0" type="slide" range="0 0.04"/>
      </default>
      <default class="visual">
        <geom type="mesh" contype="0" conaffinity="0" group="2"/>
      </default>
      <default class="collision">
        <geom type="mesh" group="3"/>
        <default class="fingertip_pad_collision_1">
          <geom type="box" size="0.0085 0.004 0.0085" pos="0 0.0055 0.0445"/>
        </default>
        <default class="fingertip_pad_collision_2">
          <geom type="box" size="0.003 0.002 0.003" pos="0.0055 0.002 0.05"/>
        </default>
        <default class="fingertip_pad_collision_3">
          <geom type="box" size="0.003 0.002 0.003" pos="-0.0055 0.002 0.05"/>
        </default>
        <default class="fingertip_pad_collision_4">
          <geom type="box" size="0.003 0.002 0.0035" pos="0.0055 0.002 0.0395"/>
        </default>
        <default class="fingertip_pad_collision_5">
          <geom type="box" size="0.003 0.002 0.0035" pos="-0.0055 0.002 0.0395"/>
        </default>
        <default class="tcp_axis">
            <geom type="cylinder" size="0.001" contype="0" conaffinity="0" group="4"/>
        </default>
      </default>
    </default>
    <default class="gripper">
      <joint range="0 0.943"/>
      <general dyntype="none" gaintype="fixed" biastype="affine"
               dynprm="1 0 0" gainprm="10 0 0" biasprm="0 -10 -0.1"
               forcerange="-10 10" ctrlrange="0 0.943"/>
    </default>
    <default class="ag_visual">
      <geom group="2" type="mesh" contype="0" conaffinity="0" density="0"/>
    </default>
    <default class="ag_collision">
      <geom group="3" type="mesh" density="2700"/>
      <default class="pad_box_0">
        <geom solimp="0.95 0.99 0.001" solref="0.004 1" priority="1" rgba="0.45 0.45 0.45 1"/>
      </default>
      <default class="pad_box_1">
        <geom solimp="0.95 0.99 0.001" solref="0.004 1" priority="1" rgba="0.55 0.55 0.55 1"/>
      </default>
      <default class="sphere_collision">
        <geom type="sphere" size="0.0006" group="3" solimp="0.95 0.99 0.001" solref="0.004 1"
              priority="1" mass="1e-6" rgba="1 0 0 1"/>
      </default>
    </default>
  </default>
  <asset>
    <material class="panda_arm_only" name="white" rgba="1 1 1 1"/>
    <material class="panda_arm_only" name="off_white" rgba="0.901961 0.921569 0.929412 1"/>
    <material class="panda_arm_only" name="black" rgba="0.25 0.25 0.25 1"/>
    <material class="panda_arm_only" name="green" rgba="0 1 0 1"/>
    <material class="panda_arm_only" name="light_blue" rgba="0.039216 0.541176 0.780392 1"/>

    <!-- Collision meshes -->
    <mesh name="link0_c" file="link0.stl"/>
    <mesh name="link1_c" file="link1.stl"/>
    <mesh name="link2_c" file="link2.stl"/>
    <mesh name="link3_c" file="link3.stl"/>
    <mesh name="link4_c" file="link4.stl"/>
    <mesh name="link5_c0" file="link5_collision_0.obj"/>
    <mesh name="link5_c1" file="link5_collision_1.obj"/>
    <mesh name="link5_c2" file="link5_collision_2.obj"/>
    <mesh name="link6_c" file="link6.stl"/>
    <mesh name="link7_c" file="link7.stl"/>

    <!-- Visual meshes -->
    <mesh file="link0_0.obj"/>
    <mesh file="link0_1.obj"/>
    <mesh file="link0_2.obj"/>
    <mesh file="link0_3.obj"/>
    <mesh file="link0_4.obj"/>
    <mesh file="link0_5.obj"/>
    <mesh file="link0_7.obj"/>
    <mesh file="link0_8.obj"/>
    <mesh file="link0_9.obj"/>
    <mesh file="link0_10.obj"/>
    <mesh file="link0_11.obj"/>
    <mesh file="link1.obj"/>
    <mesh file="link2.obj"/>
    <mesh file="link3_0.obj"/>
    <mesh file="link3_1.obj"/>
    <mesh file="link3_2.obj"/>
    <mesh file="link3_3.obj"/>
    <mesh file="link4_0.obj"/>
    <mesh file="link4_1.obj"/>
    <mesh file="link4_2.obj"/>
    <mesh file="link4_3.obj"/>
    <mesh file="link5_0.obj"/>
    <mesh file="link5_1.obj"/>
    <mesh file="link5_2.obj"/>
    <mesh file="link6_0.obj"/>
    <mesh file="link6_1.obj"/>
    <mesh file="link6_2.obj"/>
    <mesh file="link6_3.obj"/>
    <mesh file="link6_4.obj"/>
    <mesh file="link6_5.obj"/>
    <mesh file="link6_6.obj"/>
    <mesh file="link6_7.obj"/>
    <mesh file="link6_8.obj"/>
    <mesh file="link6_9.obj"/>
    <mesh file="link6_10.obj"/>
    <mesh file="link6_11.obj"/>
    <mesh file="link6_12.obj"/>
    <mesh file="link6_13.obj"/>
    <mesh file="link6_14.obj"/>
    <mesh file="link6_15.obj"/>
    <mesh file="link6_16.obj"/>
    <mesh file="link7_0.obj"/>
    <mesh file="link7_1.obj"/>
    <mesh file="link7_2.obj"/>
    <mesh file="link7_3.obj"/>
    <mesh file="link7_4.obj"/>
    <mesh file="link7_5.obj"/>
    <mesh file="link7_6.obj"/>
    <mesh file="link7_7.obj"/>
    <material name="grey" specular="0.5" shininess="0.25" rgba="0.51764705882 0.53764705882 0.54764705882 1"/>
    <material name="ebony" specular="0.5" shininess="0.25" rgba="0.1 0.1 0.1 1"/>
    <mesh name="base_link" file="base_link.stl" scale="0.001 0.001 0.001"/>
    <mesh name="gripper_body" file="gripper_body.stl" scale="0.001 0.001 0.001"/>
    <mesh name="outer_knuckle" file="outer_knuckle.stl" scale="0.001 0.001 0.001"/>
    <mesh name="inner_knuckle" file="inner_knuckle.stl" scale="0.001 0.001 0.001"/>
    <mesh name="finger" file="finger.stl" scale="0.001 0.001 0.001"/>
    <mesh name="finger_pad_0" file="finger_pad_0.stl" scale="1 1 1"/>
    <mesh name="finger_pad_1" file="finger_pad_1.stl" scale="1 1 1"/>
  </asset>
  <worldbody>
    <light name="top" pos="0 0 2" mode="trackcom"/>
    <body name="link0" childclass="panda_arm_only">
      <inertial mass="0.629769" pos="-0.041018 -0.00014 0.049974" fullinertia="0.00315 0.00388 0.004285 8.2904e-7 0.00015 8.2299e-6"/>
      <geom mesh="link0_0" material="off_white" class="visual"/>
      <geom mesh="link0_1" material="black" class="visual"/>
      <geom mesh="link0_2" material="off_white" class="visual"/>
      <geom mesh="link0_3" material="black" class="visual"/>
      <geom mesh="link0_4" material="off_white" class="visual"/>
      <geom mesh="link0_5" material="black" class="visual"/>
      <geom mesh="link0_7" material="white" class="visual"/>
      <geom mesh="link0_8" material="white" class="visual"/>
      <geom mesh="link0_9" material="black" class="visual"/>
      <geom mesh="link0_10" material="off_white" class="visual"/>
      <geom mesh="link0_11" material="white" class="visual"/>
      <geom mesh="link0_c" class="collision"/>
      <body name="link1" pos="0 0 0.333">
        <inertial mass="4.970684" pos="0.003875 0.002081 -0.04762" fullinertia="0.70337 0.70661 0.0091170 -0.00013900 0.0067720 0.019169"/>
        <joint name="joint1" axis="0 0 1" range="-2.8973 2.8973"/>
        <geom material="white" mesh="link1" class="visual"/>
        <geom mesh="link1_c" class="collision"/>
        <body name="link2" quat="1 -1 0 0">
          <inertial mass="0.646926" pos="-0.003141 -0.02872 0.003495" fullinertia="0.0079620 2.8110e-2 2.5995e-2 -3.925e-3 1.0254e-2 7.04e-4"/>
          <joint name="joint2" axis="0 0 1" range="-1.7628 1.7628"/>
          <geom material="white" mesh="link2" class="visual"/>
          <geom mesh="link2_c" class="collision"/>
          <body name="link3" pos="0 -0.316 0" quat="1 1 0 0">
            <joint name="joint3" axis="0 0 1" range="-2.8973 2.8973"/>
            <inertial mass="3.228604" pos="0.027518 0.039252 -0.066502" fullinertia="0.037242 0.036155 0.01083 -0.004761 -0.011396 -0.012805"/>
            <geom mesh="link3_0" material="white" class="visual"/>
            <geom mesh="link3_1" material="white" class="visual"/>
            <geom mesh="link3_2" material="white" class="visual"/>
            <geom mesh="link3_3" material="black" class="visual"/>
            <geom mesh="link3_c" class="collision"/>
            <body name="link4" pos="0.0825 0 0" quat="1 1 0 0">
              <inertial mass="3.587895" pos="-0.05317 0.104419 0.027454" fullinertia="0.025853 0.019552 0.028323 0.007796 -0.001332 0.008641"/>
              <joint name="joint4" axis="0 0 1" range="-3.0718 -0.0698"/>
              <geom mesh="link4_0" material="white" class="visual"/>
              <geom mesh="link4_1" material="white" class="visual"/>
              <geom mesh="link4_2" material="black" class="visual"/>
              <geom mesh="link4_3" material="white" class="visual"/>
              <geom mesh="link4_c" class="collision"/>
              <body name="link5" pos="-0.0825 0.384 0" quat="1 -1 0 0">
                <inertial mass="1.225946" pos="-0.011953 0.041065 -0.038437" fullinertia="0.035549 0.029474 0.008627 -0.002117 -0.004037 0.000229"/>
                <joint name="joint5" axis="0 0 1" range="-2.8973 2.8973"/>
                <geom mesh="link5_0" material="black" class="visual"/>
                <geom mesh="link5_1" material="white" class="visual"/>
                <geom mesh="link5_2" material="white" class="visual"/>
                <geom mesh="link5_c0" class="collision"/>
                <geom mesh="link5_c1" class="collision"/>
                <geom mesh="link5_c2" class="collision"/>
                <body name="link6" quat="1 1 0 0">
                  <inertial mass="1.666555" pos="0.060149 -0.014117 -0.010517" fullinertia="0.001964 0.004354 0.005433 0.000109 -0.001158 0.000341"/>
                  <joint name="joint6" axis="0 0 1" range="-0.0175 3.7525"/>
                  <geom mesh="link6_0" material="off_white" class="visual"/>
                  <geom mesh="link6_1" material="white" class="visual"/>
                  <geom mesh="link6_2" material="black" class="visual"/>
                  <geom mesh="link6_3" material="white" class="visual"/>
                  <geom mesh="link6_4" material="white" class="visual"/>
                  <geom mesh="link6_5" material="white" class="visual"/>
                  <geom mesh="link6_6" material="white" class="visual"/>
                  <geom mesh="link6_7" material="light_blue" class="visual"/>
                  <geom mesh="link6_8" material="light_blue" class="visual"/>
                  <geom mesh="link6_9" material="black" class="visual"/>
                  <geom mesh="link6_10" material="black" class="visual"/>
                  <geom mesh="link6_11" material="white" class="visual"/>
                  <geom mesh="link6_12" material="green" class="visual"/>
                  <geom mesh="link6_13" material="white" class="visual"/>
                  <geom mesh="link6_14" material="black" class="visual"/>
                  <geom mesh="link6_15" material="black" class="visual"/>
                  <geom mesh="link6_16" material="white" class="visual"/>
                  <geom mesh="link6_c" class="collision"/>
                  <body name="link7" pos="0.088 0 0" quat="1 1 0 0">
                    <inertial mass="0.735522" pos="0.010517 -0.004252 0.061597" fullinertia="0.012516 0.010027 0.004815 -0.000428 -0.001196 -0.000741"/>
                    <joint name="joint7" axis="0 0 1" range="-2.8973 2.8973"/>
                    <geom mesh="link7_0" material="white" class="visual"/>
                    <geom mesh="link7_1" material="black" class="visual"/>
                    <geom mesh="link7_2" material="black" class="visual"/>
                    <geom mesh="link7_3" material="black" class="visual"/>
                    <geom mesh="link7_4" material="black" class="visual"/>
                    <geom mesh="link7_5" material="black" class="visual"/>
                    <geom mesh="link7_6" material="black" class="visual"/>
                    <geom mesh="link7_7" material="white" class="visual"/>
                    <geom mesh="link7_c" class="collision"/>
                    <body name="ag95_mount" pos="0 0 0.1034" childclass="gripper">
                      <body name="base">
                        <geom class="ag_collision" mesh="base_link"/>
                        <geom class="ag_visual"    mesh="base_link" material="grey"/>
                        <geom class="ag_collision" mesh="gripper_body"/>
                        <geom class="ag_visual"    mesh="gripper_body" material="ebony"/>
                      </body>
                      <body name="left_inner_knuckle" pos="0.016 -0.0254 0.10586" quat="0.922844 0 0.385173 0">
                        <joint name="left_inner_knuckle_joint" axis="0 -1 0"/>
                        <geom class="ag_collision" pos="-0.016 0.0254 -0.10586" mesh="inner_knuckle"/>
                        <geom class="ag_visual"    pos="-0.016 0.0254 -0.10586" mesh="inner_knuckle" material="ebony"/>
                      </body>
                      <body name="left_outer_knuckle" pos="0.036673 -0.00875 0.098336" quat="0.924908 0 -0.380191 0">
                        <joint name="left_outer_knuckle_joint" axis="0 -1 0"/>
                        <geom class="ag_collision" pos="-0.036673 0.00875 -0.098336" mesh="outer_knuckle"/>
                        <geom class="ag_visual"    pos="-0.036673 0.00875 -0.098336" mesh="outer_knuckle" material="ebony"/>
                        <body name="left_finger" pos="0.055 0 0" quat="0.924908 0 0.380191 0">
                          <joint name="left_finger_joint" axis="0 1 0"/>
                          <geom class="ag_collision" pos="-0.091673 0.00875 -0.098336" mesh="finger"/>
                          <geom class="ag_visual"    pos="-0.091673 0.00875 -0.098336" mesh="finger" material="ebony"/>
                          <site name="left_finger_site" size="0.005" rgba="1 0 0 1"/>
                          <!-- визуальные губки -->
                          <geom class="ag_visual" mesh="finger_pad_0" material="grey"
                              pos="-0.091673 0.00875 -0.098336"/>
                          <geom class="ag_visual" mesh="finger_pad_1" material="grey"
                              pos="-0.091673 0.00875 -0.098336"/>  
                          <!-- коллизии губок -->
                          <geom class="pad_box_0" mesh="finger_pad_0"
                              pos="-0.091673 0.00875 -0.098336"/>
                          <geom class="pad_box_1" mesh="finger_pad_1"
                              pos="-0.091673 0.00875 -0.098336"/>
                        </body>
                      </body>
                      <body name="right_inner_knuckle" pos="-0.016 0.0254 0.10586" quat="0 0.385173 0 -0.922844">
                        <joint name="right_inner_knuckle_joint" axis="0 -1 0"/>
                        <geom class="ag_collision" pos="-0.016 0.0254 -0.10586" mesh="inner_knuckle"/>
                        <geom class="ag_visual"    pos="-0.016 0.0254 -0.10586" mesh="inner_knuckle" material="ebony"/>
                      </body>
                      <body name="right_outer_knuckle" pos="-0.036673 0.00875 0.098336" quat="0 0.380191 0 0.924908">
                        <joint name="right_outer_knuckle_joint" axis="0 -1 0"/>
                        <geom class="ag_collision" pos="-0.036673 0.00875 -0.098336" mesh="outer_knuckle"/>
                        <geom class="ag_visual"    pos="-0.036673 0.00875 -0.098336" mesh="outer_knuckle" material="ebony"/>
                        <body name="right_finger" pos="0.055 0 0" quat="0.924908 0 0.380191 0">
                          <joint name="right_finger_joint" axis="0 1 0"/>
                          <geom class="ag_collision" pos="-0.091673 0.00875 -0.098336" mesh="finger"/>
                          <geom class="ag_visual"    pos="-0.091673 0.00875 -0.098336" mesh="finger" material="ebony"/>
                          <site name="right_finger_site" size="0.005" rgba="0 1 0 1"/>
                          <geom class="ag_visual" mesh="finger_pad_0" material="grey"
                              pos="-0.091673 0.00875 -0.098336"/>
                          <geom class="ag_visual" mesh="finger_pad_1" material="grey"
                              pos="-0.091673 0.00875 -0.098336"/>
  
                          <geom class="pad_box_0" mesh="finger_pad_0"
                              pos="-0.091673 0.00875 -0.098336"/>
                          <geom class="pad_box_1" mesh="finger_pad_1"
                              pos="-0.091673 0.00875 -0.098336"/>
                        </body>
                      </body>
                      <body name="tcp" pos="0 0 0.15">
                        <site name="tcp_site" pos="0 0 0" type="sphere" size="0.005" rgba="1 1 0 1" group="4"/>
                        <geom name="tcp_x" class="tcp_axis" size="0.003" fromto="0 0 0   0.05 0 0" rgba="1 0 0 1"/>
                        <geom name="tcp_y" class="tcp_axis" size="0.003" fromto="0 0 0   0 0.05 0" rgba="0 1 0 1"/>
                        <geom name="tcp_z" class="tcp_axis" size="0.003" fromto="0 0 0   0 0 0.05" rgba="0 0 1 1"/>
                      </body>           
                    </body>
                  </body>
                </body>
              </body>
            </body>
          </body>
        </body>
      </body>
    </body>
  </worldbody>
  <contact>
    <exclude body1="base" body2="left_inner_knuckle"/>
    <exclude body1="base" body2="left_outer_knuckle"/>
    <exclude body1="base" body2="right_inner_knuckle"/>
    <exclude body1="base" body2="right_outer_knuckle"/>
    <exclude body1="left_inner_knuckle" body2="left_finger"/>
    <exclude body1="right_inner_knuckle" body2="right_finger"/>
  </contact>
  <tendon>
      <fixed name="split">
      <joint joint="left_outer_knuckle_joint" coef="0.5"/>
      <joint joint="right_outer_knuckle_joint" coef="0.5"/>
      </fixed>
  </tendon>
  <equality>
    <connect anchor="-0.020673 0 0.007524" body1="left_finger" body2="left_inner_knuckle" solimp="0.95 0.99 0.001" solref="0.005 1"/>
    <connect anchor="-0.020673 0 0.007524" body1="right_finger" body2="right_inner_knuckle" solimp="0.95 0.99 0.001" solref="0.005 1"/>
    <joint joint1="left_outer_knuckle_joint" joint2="right_outer_knuckle_joint" polycoef="0 1 0 0 0" solimp="0.95 0.99 0.001" solref="0.005 1"/>
  </equality>
  <actuator>
    <general class="panda_arm_only" name="actuator1" joint="joint1" gainprm="4500" biasprm="0 -4500 -450"/>
    <general class="panda_arm_only" name="actuator2" joint="joint2" gainprm="4500" biasprm="0 -4500 -450"
             ctrlrange="-1.7628 1.7628"/>
    <general class="panda_arm_only" name="actuator3" joint="joint3" gainprm="3500" biasprm="0 -3500 -350"/>
    <general class="panda_arm_only" name="actuator4" joint="joint4" gainprm="3500" biasprm="0 -3500 -350"
             ctrlrange="-3.0718 -0.0698"/>
    <general class="panda_arm_only" name="actuator5" joint="joint5" gainprm="2000" biasprm="0 -2000 -200" forcerange="-12 12"/>
    <general class="panda_arm_only" name="actuator6" joint="joint6" gainprm="2000" biasprm="0 -2000 -200" forcerange="-12 12"
             ctrlrange="-0.0175 3.7525"/>
    <general class="panda_arm_only" name="actuator7" joint="joint7" gainprm="2000" biasprm="0 -2000 -200" forcerange="-12 12"/>
    <general name="fingers_actuator" tendon="split"/>
  </actuator>
  <sensor>
    <force name="left_finger_force" site="left_finger_site"/>
    <force name="right_finger_force" site="right_finger_site"/>
  </sensor>
</mujoco>
